<mujoco model="armv5">
  <compiler angle="radian" meshdir="/home/yue/mjlab/src/mjlab/asset_zoo/robots/armv5/xmls/assets"/>

  <asset>
    <mesh name="base_link" file="base_link.STL"/>
    <mesh name="Link1" file="Link1.STL"/>
    <mesh name="Link2" file="Link2.STL"/>
    <mesh name="Link3" file="Link3.STL"/>
    <mesh name="Link4" file="Link4.STL"/>
    <mesh name="Link5" file="Link5.STL"/>
  </asset>

  <worldbody>
    <geom type="mesh" contype="0" conaffinity="0" group="1" density="0" rgba="0.77647 0.75686 0.73725 1" mesh="base_link"/>
    <geom type="mesh" rgba="0.77647 0.75686 0.73725 1" mesh="base_link"/>
    <body name="Link1" pos="0 0 0.0418">
      <inertial pos="0 0 0.0060801" quat="0.707107 0.707107 0 0" mass="0.183703" diaginertia="0.0001112 9.27e-05 2.89e-05"/>
      <joint name="joint1" pos="0 0 0" axis="0 0 -1" range="-3.14 3.14" actuatorfrcrange="-5 5"/>
      <geom type="mesh" contype="0" conaffinity="0" group="1" density="0" rgba="0.86667 0.9098 1 1" mesh="Link1"/>
      <geom type="mesh" rgba="0.86667 0.9098 1 1" mesh="Link1"/>
      <body name="Link2" pos="0.00010722 0.0010746 0.040182">
        <inertial pos="0.0010127 -0.0010746 0.085631" quat="0.999934 -0.0114962 0 0" mass="0.0927659" diaginertia="0.0006494 0.000611894 5.50056e-05"/>
        <joint name="joint2" pos="0 0 0" axis="0 1 0" range="-3.14 3.14" actuatorfrcrange="-5 5"/>
        <geom type="mesh" contype="0" conaffinity="0" group="1" density="0" rgba="0.49804 0.49804 0.49804 1" mesh="Link2"/>
        <geom type="mesh" rgba="0.49804 0.49804 0.49804 1" mesh="Link2"/>
        <body name="Link3" pos="0.032908 0.018025 0.20892">
          <inertial pos="0.14328 -0.018797 1.0906e-05" quat="0 0.707107 0 0.707107" mass="0.205471" diaginertia="0.0030519 0.0030471 1.58e-05"/>
          <joint name="joint3" pos="0 0 0" axis="0 -1 0" range="-3.14 3.14" actuatorfrcrange="-5 5"/>
          <geom type="mesh" contype="0" conaffinity="0" group="1" density="0" rgba="0.89412 0.89412 0.89412 1" mesh="Link3"/>
          <geom type="mesh" rgba="0.89412 0.89412 0.89412 1" mesh="Link3"/>
          <body name="Link4" pos="0.28658 -0.0349 1.0908e-05">
            <inertial pos="0.00038671 -0.0099523 -0.025575" quat="0.955266 0.295566 -0.00654012 -0.00807128" mass="0.0861729" diaginertia="1.43027e-05 1.20467e-05 6.25062e-06"/>
            <joint name="joint4" pos="0 0 0" axis="0 -1 0" range="-3.14 3.14" actuatorfrcrange="-5 5"/>
            <geom type="mesh" contype="0" conaffinity="0" group="1" density="0" rgba="0.49804 0.49804 0.49804 1" mesh="Link4"/>
            <geom type="mesh" rgba="0.49804 0.49804 0.49804 1" mesh="Link4"/>
            <body name="Link5" pos="0.001 0.01631 -0.0212">
              <inertial pos="-0.00019694 -6.2858e-08 -0.073183" quat="0.707107 0.707107 0 0" mass="0.0413468" diaginertia="2.56e-05 1.8e-05 1.48e-05"/>
              <joint name="joint5" pos="0 0 0" axis="0 0 -1" range="-3.14 3.14" actuatorfrcrange="-5 5"/>
              <geom type="mesh" contype="0" conaffinity="0" group="1" density="0" rgba="0.49804 0.49804 0.49804 1" mesh="Link5"/>
              <geom type="mesh" rgba="0.49804 0.49804 0.49804 1" mesh="Link5"/>
            </body>
          </body>
        </body>
      </body>
    </body>
  </worldbody>
</mujoco>
